Workbook

Sheet DINAMICS1
A1: DESLIGAMENTO | B1: (vazio) | F1: 15
H2: Escopo por módulo
A3: Contagem de COLABORADOR | B3: Rótulos de Coluna | H3: Assistentes: 7
A4: Rótulos de Linha | B4: Assistente Operador Carregamento Grua | C4: Oper Maqs Florestais I Grua | D4: Total Geral | F4: Falta para completar HC | H4: Operadores: 8
A5: MOD.01 | B5: 8 | C5: 9 | D5: 17 | H5: Total: 15
A6: MOD.02 | B6: 7 | C6: 7 | D6: 14
A7: MOD.03 | B7: 7 | C7: 9 | D7: 16 | H7: Escopo por módulo
A8: MOD.04 | B8: 6 | C8: 8 | D8: 14 | H8: Oper Estradas: 4
A9: MOD.05 | B9: 6 | C9: 9 | D9: 15 | H9: Motorista: 3
A10: MOD.06 | B10: 6 | C10: 9 | D10: 15 | H10: Total: 7
A11: MOD.07 | B11: 6 | C11: 10 | D11: 16
A12: MOD.08 | B12: 7 | C12: 8 | D12: 15
A13: Total Geral | B13: 53 | C13: 69 | D13: 122
A15: DESLIGAMENTO | B15: (vazio)
A17: Contagem de COLABORADOR | B17: Rótulos de Coluna
A18: Rótulos de Linha | B18: MOTORISTA I | C18: MOTORISTA II | D18: OPERADOR DE ESTRADAS II | E18: OPERADOR DE ESTRADAS III | F18: OPERADOR DE ESTRADAS I | G18: Total Geral
A19: MOD.01 | C19: 3 | E19: 4 | G19: 7
A20: MOD.02 | C20: 3 | E20: 4 | G20: 7
A21: MOD.03 | C21: 3 | E21: 4 | G21: 7
A22: MOD.04 | B22: 1 | C22: 2 | E22: 3 | F22: 1 | G22: 7
A23: MOD.05 | C23: 3 | D23: 1 | E23: 3 | G23: 7
A24: MOD.06 | C24: 3 | D24: 1 | E24: 3 | G24: 7
A25: MOD.07 | B25: 1 | C25: 2 | D25: 2 | E25: 2 | G25: 7
A26: MOD.08 | C26: 1 | D26: 2 | E26: 2 | G26: 5
A27: MOD.ITINERANTE | C27: 6 | D27: 1 | E27: 5 | G27: 12
A28: Total Geral | B28: 2 | C28: 26 | D28: 7 | E28: 30 | F28: 1 | G28: 66
A35: DATA SAÍDA | B35: (vazio)
A37: Contagem de COLABORADOR | B37: Rótulos de Coluna
A38: Rótulos de Linha | B38: TECN OPERACOES FLORESTAIS II | C38: TECN OPERACOES FLORESTAIS III | D38: Total Geral
A39: MOD.01 | B39: 1 | D39: 1
A40: MOD.01/04 | B40: 1 | D40: 1
A41: MOD.02 | B41: 1 | D41: 1
A42: MOD.02/03 | B42: 1 | D42: 1
A43: MOD.03 | B43: 1 | D43: 1
A44: MOD.04 | B44: 1 | D44: 1
A45: MOD.05 | B45: 1 | D45: 1
A46: MOD.06 | B46: 1 | D46: 1
A47: MOD.06/MOD.07 | B47: 1 | D47: 1
A48: MOD.07 | B48: 1 | D48: 1
A49: MOD.08 | B49: 1 | D49: 1
...

Sheet ASSISTENTES E OPERADORES
A1: MATRÍCULA | B1: COLABORADOR | C1: MÓDULO | D1: CARGO | E1: CC | F1: GESTOR IMEDIATO | G1: MÓDULO2 | H1: ID COLABORADOR | I1: DATA ADMISSÃO | J1: SITUACAO | K1: DESLIGAMENTO | L1: Cidade Origem | M1: Prêmio de produção | O1: GESTOR | P1: MODULO | Q1: CENTRO DE CUSTO | R1: SUPERVISOR
A2: 37005668 | B2: AIRTON LOPES DA SILVA | C2: =RIGHT(Tabela3[[#This Row],[MÓDULO2]],1) -> 1 | D2: Oper Maqs Florestais I Grua | E2: 373114 | F2: MARCIO APARECIDO CAVALHEIRO | G2: MOD.01 | H2: 20013964 | I2: 44329 | J2: =Tabela3[[#This Row],[CARGO]] -> Oper Maqs Florestais I Grua | L2: Lençóis Paulista | M2: Prêmio Maio - ok | O2: MARIO FRAIZ COELHO MAIA DE ANDRADE | Q2: 371145 - CARREG TERC CEL
A3: 37005493 | B3: ANDERSON ANTONIO HENRIQUE DE OLIVEIRA | C3: =RIGHT(Tabela3[[#This Row],[MÓDULO2]],1) -> 1 | D3: Assistente Operador Carregamento Grua | E3: 373114 | F3: MARCIO APARECIDO CAVALHEIRO | G3: MOD.01 | H3: 20013542 | I3: 44270 | J3: =Tabela3[[#This Row],[CARGO]] -> Assistente Operador Carregamento Grua | L3: Lençóis Paulista | M3: Prêmio Maio - ok | O3: MARIO FRAIZ COELHO MAIA DE ANDRADE | Q3: 371150 - CARREG TERC ENE
A4: 37000092 | B4: APARECIDO RODRIGUES DE SOUZA | C4: =RIGHT(Tabela3[[#This Row],[MÓDULO2]],1) -> 1 | D4: Assistente Operador Carregamento Grua | E4: 373114 | F4: MARCIO APARECIDO CAVALHEIRO | G4: MOD.01 | H4: 20008678 | I4: 33795 | J4: =Tabela3[[#This Row],[CARGO]] -> Assistente Operador Carregamento Grua | L4: Lençóis Paulista | M4: Prêmio Maio - ok | O4: MARIO FRAIZ COELHO MAIA DE ANDRADE | P4: MOD.01 | Q4: 371171 - CARREG PROP MOD 1 | R4: MARCIO APARECIDO CAVALHEIRO
A5: 37012429 | B5: CELIO ALVES DOS SANTOS | C5: =RIGHT(Tabela3[[#This Row],[MÓDULO2]],1) -> 1 | D5: Oper Maqs Florestais I Grua | E5: 373114 | F5: MARCIO APARECIDO CAVALHEIRO | G5: MOD.01 | H5: 20049729 | I5: 45055 | J5: =Tabela3[[#This Row],[CARGO]] -> Oper Maqs Florestais I Grua | L5: Lençóis Paulista (guede) | M5: Prêmio Maio - ok | O5: MARIO FRAIZ COELHO MAIA DE ANDRADE | P5: MOD.02 | Q5: 371172 - CARREG PROP MOD 2 | R5: JHON FELIPE SENOSKI
A6: 37018299 | B6: CLAUDIVAN APARECIDO SOARES DE GOES | C6: =RIGHT(Tabela3[[#This Row],[MÓDULO2]],1) -> 1 | D6: Oper Maqs Florestais I Grua | E6: 373114 | F6: MARCIO APARECIDO CAVALHEIRO | G6: MOD.01 | H6: 20072858 | I6: 45475 | J6: =Tabela3[[#This Row],[CARGO]] -> Oper Maqs Florestais I Grua | L6: Lençóis Paulista | M6: Prêmio Maio - ok | O6: MARIO FRAIZ COELHO MAIA DE ANDRADE | P6: MOD.03 | Q6: 371173 - CARREG PROP MOD 3 | R6: JHON FELIPE SENOSKI
A7: 37006523 | B7: CRISTIAN APARECIDO DE MELO | C7: =RIGHT(Tabela3[[#This Row],[MÓDULO2]],1) -> 1 | D7: Assistente Operador Carregamento Grua | E7: 373114 | F7: MARCIO APARECIDO CAVALHEIRO | G7: MOD.01 | H7: 20018115 | I7: 44473 | J7: =Tabela3[[#This Row],[CARGO]] -> Assistente Operador Carregamento Grua | L7: Lençóis Paulista | M7: Prêmio Maio - ok | O7: MARIO FRAIZ COELHO MAIA DE ANDRADE | P7: MOD.04 | Q7: 371174 - CARREG PROP MOD 4 | R7: MARCIO APARECIDO CAVALHEIRO
A8: 37000868 | B8: CUSTODIO XAVIER | C8: =RIGHT(Tabela3[[#This Row],[MÓDULO2]],1) -> 1 | D8: Assistente Operador Carregamento Grua | E8: 373114 | F8: MARCIO APARECIDO CAVALHEIRO | G8: MOD.01 | H8: 20008845 | I8: 40700 | J8: =Tabela3[[#This Row],[CARGO]] -> Assistente Operador Carregamento Grua | L8: Lençóis Paulista | M8: Prêmio Maio - ok | O8: MARIO FRAIZ COELHO MAIA DE ANDRADE | P8: MOD.05 | Q8: 371175 - CARREG PROP MOD 5 | R8: THIAGO MARIA PROENCA ALMEIDA
A9: 37012287 | B9: ELIELSON ANGELO DE OLIVEIRA | C9: =RIGHT(Tabela3[[#This Row],[MÓDULO2]],1) -> 1 | D9: Oper Maqs Florestais I Grua | E9: 373114 | F9: MARCIO APARECIDO CAVALHEIRO | G9: MOD.01 | H9: 20049233 | I9: 45048 | J9: =Tabela3[[#This Row],[CARGO]] -> Oper Maqs Florestais I Grua | L9: Lençóis Paulista (guede) | M9: Prêmio Maio - ok | O9: MARIO FRAIZ COELHO MAIA DE ANDRADE | P9: MOD.06 | Q9: 371176 - CARREG PROP MOD 6 | R9: CASSIO THOMAS DA SILVEIRA
A10: 37001860 | B10: JOSE DOS SANTOS SILVA | C10: =RIGHT(Tabela3[[#This Row],[MÓDULO2]],1) -> 1 | D10: Assistente Operador Carregamento Grua | E10: 373114 | F10: MARCIO APARECIDO CAVALHEIRO | G10: MOD.01 | H10: 20009387 | I10: 42758 | J10: =Tabela3[[#This Row],[CARGO]] -> Assistente Operador Carregamento Grua | L10: Lençóis Paulista | M10: Prêmio Maio - ok | O10: MARIO FRAIZ COELHO MAIA DE ANDRADE | P10: MOD.07 | Q10: 371177 - CARREG PROP MOD 7 | R10: CASSIO THOMAS DA SILVEIRA
A11: 37005646 | B11: JURANDIR APARECIDO CRISOSTOMO | C11: =RIGHT(Tabela3[[#This Row],[MÓDULO2]],1) -> 1 | D11: Oper Maqs Florestais I Grua | E11: 373114 | F11: MARCIO APARECIDO CAVALHEIRO | G11: MOD.01 | H11: 20013945 | I11: 44329 | J11: =Tabela3[[#This Row],[CARGO]] -> Oper Maqs Florestais I Grua | L11: Lençóis Paulista | M11: Prêmio Maio - ok | O11: MARIO FRAIZ COELHO MAIA DE ANDRADE | P11: MOD.08 | Q11: 371178 - CARREG PROP MOD 8 | R11: THIAGO MARIA PROENCA ALMEIDA
A12: 37002172 | B12: MAGAIVER MOREIRA | C12: =RIGHT(Tabela3[[#This Row],[MÓDULO2]],1) -> 1 | D12: Assistente Operador Carregamento Grua | E12: 373114 | F12: MARCIO APARECIDO CAVALHEIRO | G12: MOD.01 | H12: 20009576 | I12: 43122 | J12: =Tabela3[[#This Row],[CARGO]] -> Assistente Operador Carregamento Grua | L12: Lençóis Paulista | M12: Prêmio Maio - ok | O12: MARIO FRAIZ COELHO MAIA DE ANDRADE | Q12: 373105 - COORD CARREGAMENTO
A13: 37020614 | B13: MARCELO SUPARTO DA SILVA | C13: =RIGHT(Tabela3[[#This Row],[MÓDULO2]],1) -> 1 | D13: Oper Maqs Florestais I Grua | E13: 373114 | F13: MARCIO APARECIDO CAVALHEIRO | G13: MOD.01 | H13: 20084368 | I13: 45678 | J13: =Tabela3[[#This Row],[CARGO]] -> Oper Maqs Florestais I Grua | M13: Prêmio Maio - ok
A14: 37005674 | B14: MARCIO ANDRE DOS SANTOS | C14: =RIGHT(Tabela3[[#This Row],[MÓDULO2]],1) -> 1 | D14: Oper Maqs Florestais I Grua | E14: 373114 | F14: MARCIO APARECIDO CAVALHEIRO | G14: MOD.01 | H14: 20013969 | I14: 44329 | J14: =Tabela3[[#This Row],[CARGO]] -> Oper Maqs Florestais I Grua | L14: Lençóis Paulista | M14: Prêmio Maio - ok
B15: FABRICIO RODRIGUES PONTES | C15: =RIGHT(Tabela3[[#This Row],[MÓDULO2]],1) -> 1 | D15: Oper Maqs Florestais I Grua | E15: 373114 | F15: MARCIO APARECIDO CAVALHEIRO | G15: MOD.01 | I15: 44329 | J15: =Tabela3[[#This Row],[CARGO]] -> Oper Maqs Florestais I Grua | K15: 45408
B16: JULIO CESAR CORREA DA SILVA | C16: =RIGHT(Tabela3[[#This Row],[MÓDULO2]],1) -> 1 | D16: Oper Maqs Florestais I Grua | E16: 373114 | F16: MARCIO APARECIDO CAVALHEIRO | G16: MOD.01 | I16: 44329 | J16: =Tabela3[[#This Row],[CARGO]] -> Oper Maqs Florestais I Grua | K16: 45394
A17: 37005669 | B17: ODAIR DONIZETTI IZIDORO DA SILVA | C17: =RIGHT(Tabela3[[#This Row],[MÓDULO2]],1) -> 1 | D17: Assistente Operador Carregamento Grua | E17: 373114 | F17: MARCIO APARECIDO CAVALHEIRO | G17: MOD.01 | H17: 20013965 | I17: 44329 | J17: =Tabela3[[#This Row],[CARGO]] -> Assistente Operador Carregamento Grua | L17: Lençóis Paulista | M17: Prêmio Maio - ok
A18: 37007174 | B18: PAULO RODRIGUES DOS ANJOS | C18: =RIGHT(Tabela3[[#This Row],[MÓDULO2]],1) -> 1 | D18: Oper Maqs Florestais I Grua | E18: 373114 | F18: MARCIO APARECIDO CAVALHEIRO | G18: MOD.01 | H18: 20022977 | I18: 44609 | J18: =Tabela3[[#This Row],[CARGO]] -> Oper Maqs Florestais I Grua | L18: Areiópolis | M18: Prêmio Maio - ok
A19: 37001934 | B19: VAGNER PEREIRA DOS SANTOS | C19: =RIGHT(Tabela3[[#This Row],[MÓDULO2]],1) -> 1 | D19: Assistente Operador Carregamento Grua | E19: 373114 | F19: MARCIO APARECIDO CAVALHEIRO | G19: MOD.01 | H19: 20009981 | I19: 42828 | J19: =Tabela3[[#This Row],[CARGO]] -> Assistente Operador Carregamento Grua | L19: Lençóis Paulista | M19: Prêmio Maio - ok
A20: 37005672 | B20: WESLEY ROBSON FERREIRA DA SILVA | C20: =RIGHT(Tabela3[[#This Row],[MÓDULO2]],1) -> 1 | D20: Oper Maqs Florestais I Grua | E20: 373114 | F20: MARCIO APARECIDO CAVALHEIRO | G20: MOD.01 | H20: 20013968 | I20: 44329 | J20: =Tabela3[[#This Row],[CARGO]] -> Oper Maqs Florestais I Grua | L20: Lençóis Paulista | M20: Prêmio Maio - ok
B21: CRISTIANO FERREIRA SANTOS | C21: =RIGHT(Tabela3[[#This Row],[MÓDULO2]],1) -> 2 | D21: Assistente Operador Carregamento Grua | E21: 373114 | F21: JHON FELIPE SENOSKI | G21: MOD.02 | H21: 20014383 | I21: 44329 | J21: =Tabela3[[#This Row],[CARGO]] -> Assistente Operador Carregamento Grua | K21: 45758 | L21: Itapeva
B22: JULIO CESAR OLIVEIRA SANTOS | C22: =RIGHT(Tabela3[[#This Row],[MÓDULO2]],1) -> 2 | D22: Oper Maqs Florestais I Grua | E22: 373114 | F22: JHON FELIPE SENOSKI | G22: MOD.02 | H22: 20055398 | I22: 45125 | J22: =Tabela3[[#This Row],[CARGO]] -> Oper Maqs Florestais I Grua | K22: 45677 | L22: Itapeva
A23: 37015497 | B23: ELISEU BUENO DE PAULO | C23: =RIGHT(Tabela3[[#This Row],[MÓDULO2]],1) -> 2 | D23: Oper Maqs Florestais I Grua | E23: 373114 | F23: JHON FELIPE SENOSKI | G23: MOD.02 | H23: 20062748 | I23: 45265 | J23: =Tabela3[[#This Row],[CARGO]] -> Oper Maqs Florestais I Grua | L23: Itapeva | M23: Prêmio Maio - ok
A24: 37018691 | B24: ENOQUE VIEIRA DE PAULO | C24: =RIGHT(Tabela3[[#This Row],[MÓDULO2]],1) -> 2 | D24: Oper Maqs Florestais I Grua | E24: 373114 | F24: JHON FELIPE SENOSKI | G24: MOD.02 | H24: 20074848 | I24: 45510 | J24: =Tabela3[[#This Row],[CARGO]] -> Oper Maqs Florestais I Grua | L24: Campina de fora | M24: Prêmio Maio - ok
A25: 37018692 | B25: ESAU VIEIRA DE PAULO | C25: =RIGHT(Tabela3[[#This Row],[MÓDULO2]],1) -> 2 | D25: Oper Maqs Florestais I Grua | E25: 373114 | F25: JHON FELIPE SENOSKI | G25: MOD.02 | H25: 20074849 | I25: 45510 | J25: =Tabela3[[#This Row],[CARGO]] -> Oper Maqs Florestais I Grua | L25: Itapeva(campina de fora) | M25: Prêmio Maio - ok
A26: 37006418 | B26: FABRICIO SANTOS PEREIRA | C26: =RIGHT(Tabela3[[#This Row],[MÓDULO2]],1) -> 2 | D26: Assistente Operador Carregamento Grua | E26: 373114 | F26: JHON FELIPE SENOSKI | G26: MOD.02 | H26: 20017828 | I26: 44459 | J26: =Tabela3[[#This Row],[CARGO]] -> Assistente Operador Carregamento Grua | L26: Itapeva | M26: Prêmio Maio - ok
A27: 37008824 | B27: FRANCISCO HENRIQUE PEREIRA DE LIMA | C27: =RIGHT(Tabela3[[#This Row],[MÓDULO2]],1) -> 2 | D27: Assistente Operador Carregamento Grua | E27: 373114 | F27: JHON FELIPE SENOSKI | G27: MOD.02 | H27: 20034927 | I27: 44777 | J27: =Tabela3[[#This Row],[CARGO]] -> Assistente Operador Carregamento Grua | L27: Itapeva | M27: Prêmio Maio - ok
A28: 37013385 | B28: JAIR MARQUES DA SILVA FILHO | C28: =RIGHT(Tabela3[[#This Row],[MÓDULO2]],1) -> 2 | D28: Assistente Operador Carregamento Grua | E28: 373114 | F28: JHON FELIPE SENOSKI | G28: MOD.02 | H28: 20054463 | I28: 45118 | J28: =Tabela3[[#This Row],[CARGO]] -> Assistente Operador Carregamento Grua | L28: Capão bonito | M28: Prêmio Maio - ok
A29: 37005649 | B29: JEFERSON DE PAULA SILVA | C29: =RIGHT(Tabela3[[#This Row],[MÓDULO2]],1) -> 2 | D29: Assistente Operador Carregamento Grua | E29: 373114 | F29: JHON FELIPE SENOSKI | G29: MOD.02 | H29: 20013948 | I29: 44329 | J29: =Tabela3[[#This Row],[CARGO]] -> Assistente Operador Carregamento Grua | L29: Itapeva | M29: Prêmio Maio - ok
A30: 37009369 | B30: JORGE FLEXA BARBOSA | C30: =RIGHT(Tabela3[[#This Row],[MÓDULO2]],1) -> 2 | D30: Assistente Operador Carregamento Grua | E30: 373114 | F30: JHON FELIPE SENOSKI | G30: MOD.02 | H30: 20033390 | I30: 44816 | J30: =Tabela3[[#This Row],[CARGO]] -> Assistente Operador Carregamento Grua | L30: Itapeva | M30: Prêmio Maio - ok
A31: 37021674 | B31: LEONARDO DONIAS ROCHA FURQUIM | C31: =RIGHT(Tabela3[[#This Row],[MÓDULO2]],1) -> 2 | D31: Oper Maqs Florestais I Grua | E31: 373114 | F31: JHON FELIPE SENOSKI | G31: MOD.02 | H31: 20089575 | I31: 45755 | J31: =Tabela3[[#This Row],[CARGO]] -> Oper Maqs Florestais I Grua | L31: Itapeva | M31: pagar proporcional
A32: 37005645 | B32: MARCIO ROGERIO BARREIROS | C32: =RIGHT(Tabela3[[#This Row],[MÓDULO2]],1) -> 2 | D32: Assistente Operador Carregamento Grua | E32: 373114 | F32: JHON FELIPE SENOSKI | G32: MOD.02 | H32: 20014382 | I32: 44329 | J32: =Tabela3[[#This Row],[CARGO]] -> Assistente Operador Carregamento Grua | L32: Itapeva | M32: Prêmio Maio - ok
A33: 37009096 | B33: MAYCON COTA LOPES | C33: =RIGHT(Tabela3[[#This Row],[MÓDULO2]],1) -> 2 | D33: Oper Maqs Florestais I Grua | E33: 373114 | F33: JHON FELIPE SENOSKI | G33: MOD.02 | H33: 20031522 | I33: 44788 | J33: =Tabela3[[#This Row],[CARGO]] -> Oper Maqs Florestais I Grua | L33: Nova campinas | M33: Prêmio Maio - ok
A34: 37011081 | B34: MOIZES RODRIGUES FERREIRA | C34: =RIGHT(Tabela3[[#This Row],[MÓDULO2]],1) -> 2 | D34: Oper Maqs Florestais I Grua | E34: 373114 | F34: JHON FELIPE SENOSKI | G34: MOD.02 | H34: 20042153 | I34: 44963 | J34: =Tabela3[[#This Row],[CARGO]] -> Oper Maqs Florestais I Grua | L34: Itapeva | M34: Prêmio Maio - ok
B35: LEANDRO FERREIRA DE ALMEIDA | C35: =RIGHT(Tabela3[[#This Row],[MÓDULO2]],1) -> 2 | D35: Oper Maqs Florestais I Grua | E35: 373114 | F35: JHON FELIPE SENOSKI | G35: MOD.02 | I35: 44900 | J35: =Tabela3[[#This Row],[CARGO]] -> Oper Maqs Florestais I Grua | K35: 45366
B36: WESLEY AMARAL CAMARGO | C36: =RIGHT(Tabela3[[#This Row],[MÓDULO2]],1) -> 2 | D36: Assistente Operador Carregamento Grua | E36: 373114 | F36: JHON FELIPE SENOSKI | G36: MOD.02 | I36: 44329 | J36: =Tabela3[[#This Row],[CARGO]] -> Assistente Operador Carregamento Grua | K36: 45359
A37: 37011476 | B37: SALATIEL FRANCO BOACHAQUES | C37: =RIGHT(Tabela3[[#This Row],[MÓDULO2]],1) -> 2 | D37: Oper Maqs Florestais I Grua | E37: 373114 | F37: JHON FELIPE SENOSKI | G37: MOD.02 | H37: 20044135 | I37: 44991 | J37: =Tabela3[[#This Row],[CARGO]] -> Oper Maqs Florestais I Grua | L37: Itapeva | M37: Prêmio Maio - ok
A38: 37011488 | B38: THIAGO VINICIUS DE MOURA DUARTE | C38: =RIGHT(Tabela3[[#This Row],[MÓDULO2]],1) -> 2 | D38: Assistente Operador Carregamento Grua | E38: 373114 | F38: JHON FELIPE SENOSKI | G38: MOD.02 | H38: 20044147 | I38: 44991 | J38: =Tabela3[[#This Row],[CARGO]] -> Assistente Operador Carregamento Grua | L38: Itapeva | M38: Prêmio Maio - ok
A39: 37005782 | B39: AMARILDO RODRIGUES DE PAULA | C39: =RIGHT(Tabela3[[#This Row],[MÓDULO2]],1) -> 3 | D39: Assistente Operador Carregamento Grua | E39: 373114 | F39: JHON FELIPE SENOSKI | G39: MOD.03 | H39: 20016046 | I39: 44348 | J39: =Tabela3[[#This Row],[CARGO]] -> Assistente Operador Carregamento Grua | L39: Itatinga | M39: Prêmio Maio - ok
A40: 37020619 | B40: Bruno De Souza | C40: =RIGHT(Tabela3[[#This Row],[MÓDULO2]],1) -> 3 | D40: Oper Maqs Florestais I Grua | E40: 373114 | F40: JHON FELIPE SENOSKI | G40: MOD.03 | H40: 20084373 | I40: 45678 | J40: =Tabela3[[#This Row],[CARGO]] -> Oper Maqs Florestais I Grua | M40: Prêmio Maio - ok
...

Sheet Planilha1
B3: Nome atual | C3: Nome correto
B4: Claudivan Goes | C4: CLAUDIVAN APARECIDO SOARES DE GOES
B5: Wellingto Cordeiro Enoque | C5: Wellington Lopes Cordeiro Enoque
B6: Carlos Junior | C6: CARLOS ERVINO ZILLMER JUNIOR
B7: Gileno Santos De Oliveira | C7: GILENO DOS SANTOS OLIVEIRA
B8: Anderson Ávila Vaz | C8: ANDERSON AVILA VAZ
B9: Alex Da Silva | C9: Alex Varanda Da Silva
B10: Giuliano Povoas | C10: GIULIANO CARILO PÓVOAS
B11: Jaziel Araujo Ee3478525387 | C11: JAZIEL DOS SANTOS ARAUJO
B12: Esau Paulo | C12: ESAU VIEIRA DE PAULO
B13: Denis Valdiviezo | C13: Denis Visael Guerra Valdiviezo
B14: Enoque Paulo | C14: ENOQUE VIEIRA DE PAULO

Sheet SUPERVISORES E TECNICOS
A1: MATRÍCULA | B1: COLABORADOR | C1: MÓDULO | D1: CARGO | E1: TELEFONE | F1: CC 2024 | G1: GESTOR IMEDIATO | H1: COD. CARGO | I1: CARGO Workday | J1: ID COLABORADOR | K1: DATA ADMISSÃO | L1: DATA SAÍDA | M1: Cidade Origem | N1: Celular Corporativo | O1: Modelo celular | P1: GESTOR | Q1: MODULO | R1: CENTRO DE CUSTO | S1: SUPERVISOR
A2: 37009708 | B2: MARIO FRAIZ COELHO MAIA DE ANDRADE | C2: - | D2: Coordenador Logistica Florestal | E2: (14) 99667-5441 | F2: 373105 | G2: THIAGO PETINE | I2: COORD LOGISTICA FLORESTAL | J2: 20036000 | K2: 44851 | M2: Bauru | N2: Sim | O2: A32 | P2: MARIO FRAIZ COELHO MAIA DE ANDRADE | R2: 371145 - CARREG TERC CEL
A3: 37010748 | B3: CASSIO THOMAS DA SILVEIRA | C3: MOD.06/07 | D3: Supervisor Logistica Florestal | E3: (14)99688-5697 | F3: 373105 | G3: MARIO FRAIZ COELHO MAIA DE ANDRADE | H3: 11213 | I3: SUP LOGISTICA | J3: 20040958 | K3: 44935 | M3: Bauru | N3: Sim | O3: A54 | P3: MARIO FRAIZ COELHO MAIA DE ANDRADE | R3: 371150 - CARREG TERC ENE
A4: 37014825 | B4: GILLIARD LEPINSCK | C4: MOD.11 | D4: Supervisor Logistica Florestal | E4: (14) 99700-3090 | F4: 373110 | G4: Angelo Antonio Martins Taparo | H4: 11213 | I4: SUP LOGISTICA - estradas | J4: 20060104 | K4: 45202 | M4: João Pinheiro | N4: Sim | O4: A54 | P4: MARIO FRAIZ COELHO MAIA DE ANDRADE | Q4: MOD.01 | R4: 371171 - CARREG PROP MOD 1 | S4: MARCIO APARECIDO CAVALHEIRO
A5: 37005275 | B5: JHON FELIPE SENOSKI | C5: MOD.02/03 | D5: Supervisor Logistica Florestal | E5: (14) 99653-3705 | F5: 373105 | G5: MARIO FRAIZ COELHO MAIA DE ANDRADE | H5: 11213 | I5: SUP LOGISTICA | J5: 20011084 | K5: 44152 | M5: São Miguel Arcanjo | N5: Sim | O5: A54 | P5: MARIO FRAIZ COELHO MAIA DE ANDRADE | Q5: MOD.02 | R5: 371172 - CARREG PROP MOD 2 | S5: JHON FELIPE SENOSKI
A6: 37005502 | B6: MARCIO APARECIDO CAVALHEIRO | C6: MOD.01/04/10 | D6: Supervisor Logistica Florestal | E6: (14) 99608-6640 | F6: 373105 | G6: MARIO FRAIZ COELHO MAIA DE ANDRADE | H6: 11213 | I6: SUP LOGISTICA | J6: 20013549 | K6: 44270 | M6: Lençóis Paulista | N6: Sim | O6: A54 | P6: MARIO FRAIZ COELHO MAIA DE ANDRADE | Q6: MOD.03 | R6: 371173 - CARREG PROP MOD 3 | S6: JHON FELIPE SENOSKI
A7: 37013157 | B7: THIAGO MARIA PROENCA ALMEIDA | C7: MOD.05/08 | D7: Supervisor Logistica Florestal | E7: (14) 99694-2943 | F7: 373105 | G7: MARIO FRAIZ COELHO MAIA DE ANDRADE | H7: 11213 | I7: SUP LOGISTICA | J7: 20053284 | K7: 45111 | M7: Bauru | N7: Sim | O7: A53 | P7: MARIO FRAIZ COELHO MAIA DE ANDRADE | Q7: MOD.04 | R7: 371174 - CARREG PROP MOD 4 | S7: MARCIO APARECIDO CAVALHEIRO
A8: 37005557 | B8: VANDERLEI JOSE HONORIO | C8: MOD.NOTURNO | D8: Supervisor Logistica Florestal | E8: (14) 99719-3303 | F8: 373105 | G8: MARIO FRAIZ COELHO MAIA DE ANDRADE | H8: 11213 | I8: SUP LOGISTICA FLORESTAL | J8: 20013587 | K8: 44291 | M8: Agudos | N8: Sim | O8: A54 | P8: MARIO FRAIZ COELHO MAIA DE ANDRADE | Q8: MOD.05 | R8: 371175 - CARREG PROP MOD 5 | S8: THIAGO MARIA PROENCA ALMEIDA
A9: 37006559 | B9: ANTONIO JOSE FERNANDES | C9: MOD.04 | D9: TECN OPERACOES FLORESTAIS II | E9: (14) 99854-2810 | F9: 373105 | G9: MARCIO APARECIDO CAVALHEIRO | H9: 4021 | I9: TEC OPERACOES FLORESTAL II | J9: 20018135 | K9: 44473 | M9: Bauru | N9: Sim | O9: A54 | P9: MARIO FRAIZ COELHO MAIA DE ANDRADE | Q9: MOD.06 | R9: 371176 - CARREG PROP MOD 6 | S9: CASSIO THOMAS DA SILVEIRA
A10: 37008812 | B10: CAIO DE OLIVEIRA SILVA | C10: MOD.NOTURNO | D10: TECN OPERACOES FLORESTAIS II | E10: (14) 99606-9772 | F10: 373105 | G10: VANDERLEI JOSE HONORIO | H10: 4021 | I10: TEC OPERACOES FLORESTAIS II | J10: 20036622 | K10: 44777 | M10: Itapeva | N10: Sim | O10: A54 | P10: MARIO FRAIZ COELHO MAIA DE ANDRADE | Q10: MOD.07 | R10: 371177 - CARREG PROP MOD 7 | S10: CASSIO THOMAS DA SILVEIRA
A11: 37006317 | B11: EDENILSON ADEMIR PEREIRA | C11: MOD.NOTURNO | D11: TECN OPERACOES FLORESTAIS II | E11: (14)99802-0381 | F11: JHON FELIPE SENOSKI | G11: VANDERLEI JOSE HONORIO | J11: 20017044 | K11: 44447 | M11: Botucatu | N11: Não | O11: Não possui | P11: MARIO FRAIZ COELHO MAIA DE ANDRADE | Q11: MOD.08 | R11: 371178 - CARREG PROP MOD 8 | S11: THIAGO MARIA PROENCA ALMEIDA
A12: 37014499 | B12: Eder Bernardes da Silva | C12: MOD.NOTURNO | D12: TECN OPERACOES FLORESTAIS II | E12: (14)99649-5576 | G12: VANDERLEI JOSE HONORIO | J12: 20059011 | K12: 45181 | M12: Bauru | N12: Não | O12: Não possui | P12: MARIO FRAIZ COELHO MAIA DE ANDRADE | R12: 373105 - COORD CARREGAMENTO
A13: 37015179 | B13: Edson Caldeira Barbosa | C13: MOD.NOTURNO | D13: TECN OPERACOES FLORESTAIS II | E13: (14) 99837-3443 | F13: 373105 | G13: VANDERLEI JOSE HONORIO | H13: 4021 | J13: 20061495 | K13: 45237 | M13: Bauru | N13: Não | O13: Não possui
A14: 37013006 | B14: Elias Paulo da Silva | C14: MOD.09 | D14: TECN OPERACOES FLORESTAIS II | E14: (67) 96759876 | F14: 373105 | G14: Angelo Antonio Martins Taparo | H14: 4021 | I14: TEC OPERACOES FLORESTAIS II | J14: 20052425 | K14: 45083 | M14: Campo Grande | N14: Sim | O14: A54
A15: 37020934 | B15: Emerson Luiz Barbosa de Lima | C15: MOD.NOTURNO | D15: TECN OPERACOES FLORESTAIS II | E15: (14) 99823-8111 | F15: 373105 | G15: VANDERLEI JOSE HONORIO | H15: 4021 | J15: 20085371 | K15: 45706 | M15: Marília | N15: Não | O15: Não possui
A16: 37005964 | B16: EVERTON GEREMIAS LUCHINI | C16: MOD.05 | D16: TECN OPERACOES FLORESTAIS II | E16: (14) 99883-0130 | F16: 373105 | G16: THIAGO MARIA PROENCA ALMEIDA | H16: 4021 | I16: TEC OPERACOES FLORESTAIS II | J16: 20016767 | K16: 44382 | M16: Agudos | N16: Sim | O16: A54
A17: 37010940 | B17: FRANK CEL DE SOUZA LIRA | C17: MOD.09 | D17: TECN OPERACOES FLORESTAIS II | E17: (67) 9681-4609 | F17: 373105 | G17: Angelo Antonio Martins Taparo | H17: 4021 | I17: TEC OPERACOES FLORESTAIS II | J17: 20041612 | K17: 44949 | M17: Campo Grande | N17: Sim | O17: A32
A18: 37005769 | B18: GUILHERME AFONSO MASSAGLI | C18: MOD.03 | D18: TECN OPERACOES FLORESTAIS II | E18: (14) 99864-0475 | F18: 373105 | G18: JHON FELIPE SENOSKI | H18: 4021 | I18: TEC OPERACOES FLORESTAL II | J18: 20016042 | K18: 44348 | M18: Itatinga | N18: Sim | O18: A32
A19: 37019476 | B19: Itamar Magela Severiano | C19: MOD.11 | D19: TECN OPERACOES FLORESTAIS II | E19: (14) 99609-0499 | F19: 373105 | G19: GILLIARD LEPINSCK | H19: 4021 | I19: TEC OPERACOES FLORESTAIS II - carregamento | J19: 20078661 | K19: 45573 | M19: Curvelo | N19: Sim | O19: A32
A20: 37021084 | B20: Jakson Rodrigo Ribeiro Leite | C20: MOD.11 | D20: TECN OPERACOES FLORESTAIS II | E20: (14) 99825-8819 | F20: 373105 | G20: GILLIARD LEPINSCK | H20: 4021 | J20: 20086575 | K20: 45727 | M20: João Pinheiro | N20: Sim | O20: A54
A21: 37008647 | B21: Jefferson Barbosa Prestes de Oliveira | C21: MOD.06 | D21: TECN OPERACOES FLORESTAIS II | E21: (14) 99701-3196 | F21: 373105 | G21: CASSIO THOMAS DA SILVEIRA | H21: 4021 | I21: TEC OPERACOES FLORESTAL II | J21: 20028414 | K21: 44760 | M21: Lins | N21: Sim | O21: A54
A22: 37010474 | B22: JORGE LUIS FERNANDES | C22: MOD.NOTURNO | D22: TECN OPERACOES FLORESTAIS II | E22: (14) 99631-4076 | F22: 373105 | G22: VANDERLEI JOSE HONORIO | H22: 4021 | I22: TEC OPERACOES FLORESTAIS II | J22: 20040207 | K22: 44914 | M22: Agudos | N22: Sim | O22: A54
A23: 37006674 | B23: JOSE DONIZETTE LUIZ | C23: MOD.01 | D23: TECN OPERACOES FLORESTAIS II | E23: (14) 99898-4562 | F23: 373105 | G23: MARCIO APARECIDO CAVALHEIRO | H23: 4021 | I23: TEC OPERACOES FLORESTAIS III | J23: 20019979 | K23: 44503 | M23: Lençóis Paulista | N23: Sim | O23: Moto12
A24: 37001183 | B24: JULIO CRISTINO MORENO | C24: MOD.NOTURNO | D24: TECN OPERACOES FLORESTAIS II | E24: (14) 99707-5435 | F24: 373105 | G24: VANDERLEI JOSE HONORIO | H24: 4021 | I24: TEC OPERACOES FLORESTAIS II | J24: 20009437 | K24: 41386 | M24: Lençóis Paulista | N24: Sim | O24: A32
A25: 37009320 | B25: LAERCIO DOS SANTOS CAMARGO | C25: MOD.NOTURNO | D25: TECN OPERACOES FLORESTAIS II | E25: (15) 99708-7870 | F25: 373105 | G25: VANDERLEI JOSE HONORIO | H25: 4021 | I25: TEC OPERACOES FLORESTAL II | J25: 20032608 | K25: 44809 | M25: Capão Bonito | N25: Não | O25: Perdeu o corporativo
A26: 37005933 | B26: MARCIANO BATISTA FERREIRA | C26: MOD.06/MOD.07 | D26: TECN OPERACOES FLORESTAIS II | E26: (14) 99652-4282 | F26: 373105 | G26: CASSIO THOMAS DA SILVEIRA | H26: 4021 | I26: TEC OPERACOES FLORESTAIS II | J26: 20016748 | K26: 44382 | M26: Bauru | N26: Sim | O26: A54
A27: 37015225 | B27: MARCIO RODRIGUES | C27: MOD.02/03 | D27: TECN OPERACOES FLORESTAIS II | E27: (14) 996673610 | F27: 373105 | G27: JHON FELIPE SENOSKI | H27: 4021 | I27: TEC OPERACOES FLORESTAIS II | J27: 20061883 | K27: 45237 | M27: Capão Bonito | N27: Sim | O27: A51
A28: 37006336 | B28: Mauricio Fernandes Teixeira | C28: MOD.NOTURNO | D28: TECN OPERACOES FLORESTAIS II | E28: (14)99860-7877 | G28: VANDERLEI JOSE HONORIO | K28: 44447 | M28: Lins | N28: Não | O28: Não possui
A29: 37020294 | B29: Rafael Depetris Macedo | C29: MOD.05/08 | D29: TECN OPERACOES FLORESTAIS II | E29: (41) 8873-0657 | F29: 373105 | G29: THIAGO MARIA PROENCA ALMEIDA | H29: 4021 | I29: TEC OPERACOES FLORESTAIS II | J29: 20083253 | K29: 45636 | M29: Bauru | N29: Não | O29: Não possui
A30: 37011935 | B30: RAFAEL HENRIQUE DE LIMA | C30: MOD.11 | D30: TECN OPERACOES FLORESTAIS II | E30: (14) 99884-3590 | F30: 373105 | G30: GILLIARD LEPINSCK | H30: 4021 | I30: TEC OPERACOES FLORESTAIS II - carregamento | J30: 20046764 | K30: 45019 | M30: João Pinheiro | N30: Sim | O30: A54
B31: Adriano Sanabria Flores Monte Serrat | C31: MOD.09 | D31: Supervisor Logistica Florestal | E31: (67) 99857-6011 | F31: 373105 | G31: Angelo Antonio Martins Taparo | H31: 11213 | I31: SUP TRANSPORTES | J31: 20018176 | K31: 44816 | L31: verificar data | N31: - | O31: -
B32: EZEQUIEL MERCADANTE | C32: MOD.NOTURNO | D32: TECN OPERACOES FLORESTAIS II | E32: (14) 99697-3304 | F32: 373105 | G32: VANDERLEI JOSE HONORIO | H32: 4021 | I32: TEC OPERACOES FLORESTAL II | J32: 20064721 | K32: 45706 | L32: 45719 | N32: - | O32: -
B33: NERITON PETESOL DOS SANTOS | C33: MOD.07 | D33: TECN OPERACOES FLORESTAIS II | E33: (14) 99850-9970 | F33: 373105 | G33: CASSIO THOMAS DA SILVEIRA | H33: 4021 | J33: 20032967 | K33: 45111 | L33: 45541 | N33: - | O33: -
B34: JULYGLEIBER BARBOSA SOUTO | C34: MOD.11 | D34: TECN OPERACOES FLORESTAIS II | F34: 373105 | G34: GILLIARD LEPINSCK | H34: 4021 | J34: 20069979 | K34: 44291 | L34: 45504 | N34: - | O34: -
B35: KELVIN CORDEIRO DE LIMA | C35: MOD.11 | D35: TECN OPERACOES FLORESTAIS II | F35: 373105 | G35: GILLIARD LEPINSCK | H35: 4021 | J35: 20062772 | K35: 40763 | L35: 45548 | N35: - | O35: -
B36: Denilson Paulo Amaral | C36: MOD.11 | D36: TECN OPERACOES FLORESTAIS II | E36: (31) 99743-8855 | F36: 373105 | G36: GILLIARD LEPINSCK | H36: 4021 | I36: TEC OPERACOES FLORESTAIS II - carregamento | J36: 20065472 | K36: 44333 | L36: 45692 | N36: - | O36: -
A37: 37015337 | B37: Samuel De Souza Duarte | C37: MOD.07 | D37: TECN OPERACOES FLORESTAIS II | E37: (14) 99850-9970 | F37: 373105 | G37: CASSIO THOMAS DA SILVEIRA | H37: 4021 | I37: ASSIST OP CARREGAMENTO GRUA | J37: 20062321 | K37: 45251 | M37: Marília | N37: Sim | O37: A54
B38: Matheus Pimentel Santos | C38: MOD.11 | D38: TECN OPERACOES FLORESTAIS II - estradas | F38: 373110 | G38: GILLIARD LEPINSCK | H38: 4021 | I38: TEC OPERACOES FLORESTAIS II - estradas | J38: 20080109 | K38: 45580 | L38: 45652 | N38: - | O38: -
A39: 37000921 | B39: VITOR HUGO DOS SANTOS | C39: MOD.01/04 | D39: TECN OPERACOES FLORESTAIS II | E39: (14) 99834-9289 | F39: 373105 | G39: MARCIO APARECIDO CAVALHEIRO | H39: 4021 | I39: TEC OPERACOES FLORESTAIS II | J39: 20010019 | K39: 40763 | M39: Lençóis Paulista | N39: Sim | O39: MOTOG30
A40: 37005690 | B40: WANDERLEY RODRIGUES DA SILVA | C40: MOD.02 | D40: TECN OPERACOES FLORESTAIS II | E40: (14) 99614-4396 | F40: 373105 | G40: JHON FELIPE SENOSKI | H40: 4021 | I40: TEC OPERACOES FLORESTAL II | J40: 20014475 | K40: 44333 | M40: Capão Bonito | N40: Sim | O40: MOTOG30
...

Sheet APOIO_TRANSPORTE
A1: MATRÍCULA | B1: COLABORADOR | C1: MÓDULO | D1: CARGO | E1: DATA ADMISSÃO | F1: GESTOR IMEDIATO | G1: ID COLABORADOR | H1: CARGO Workday | I1: Centro de Custo | J1: OBS PRÊMIO MAIO | K1: DESLIGAMENTO | L1: Cidade Origem | M1: Prêmio novembro | N1: RH/WD | O1: TREINAMENTO | R1: GESTOR | S1: MODULO | T1: CENTRO DE CUSTO | U1: SUPERVISOR
A2: 37016887 | B2: ADILSON JOSE DIAS DOS SANTOS | C2: MOD.03 | D2: OPERADOR DE ESTRADAS III | E2: 45363 | F2: JHON FELIPE SENOSKI | G2: 20065483 | I2: 373114 | J2: Premio maio - ok | L2: Areiopolis | M2: ok | N2: ok | R2: MARIO FRAIZ COELHO MAIA DE ANDRADE | T2: 371145 - CARREG TERC CEL
B3: PEDRO AUGUSTO PINI | C3: MOD.01 | D3: OPERADOR DE ESTRADAS III | E3: 45461 | F3: MARCIO APARECIDO CAVALHEIRO | G3: 20072331 | H3: =VLOOKUP(Apoio_Transp[[#This Row],[MATRÍCULA]],[2]!Tabela1[[#All],[ID SAP]:[NOMENCLATURA DA POSIÇÃO]],6,0) -> #REF! | I3: 373116 | K3: 45522 | R3: MARIO FRAIZ COELHO MAIA DE ANDRADE | T3: 371150 - CARREG TERC ENE
A4: 37018023 | B4: DANIEL MIRANDA | C4: MOD.02 | D4: MOTORISTA II | E4: 45454 | F4: JHON FELIPE SENOSKI | G4: 20071382 | I4: 373114 | J4: Premio maio - ok | L4: itapeva | M4: ok | N4: ok
A5: 37018978 | B5: ADEILTON MARCOS DE SOUSA | C5: MOD.04 | D5: MOTORISTA II | E5: 45538 | F5: MARCIO APARECIDO CAVALHEIRO | G5: 20076197 | I5: 373114 | J5: Premio maio - ok | L5: agudos | M5: ok | N5: Thiago abrir o desligamento dele no Worday | R5: MARIO FRAIZ COELHO MAIA DE ANDRADE | S5: MOD.01 | T5: 371171 - CARREG PROP MOD 1 | U5: MARCIO APARECIDO CAVALHEIRO
A6: 37016809 | B6: ALAN DA CRUZ GONCALVES | C6: MOD.04 | D6: OPERADOR DE ESTRADAS III | E6: 45356 | F6: MARCIO APARECIDO CAVALHEIRO | G6: 20065308 | I6: 373114 | J6: Premio maio - ok | L6: agudos | M6: ok | N6: ok | R6: MARIO FRAIZ COELHO MAIA DE ANDRADE | S6: MOD.03 | T6: 371173 - CARREG PROP MOD 3 | U6: JHON FELIPE SENOSKI
A7: 37017571 | B7: ANTONIO MARCIO AGUILERA | C7: MOD.01 | D7: MOTORISTA II | E7: 45426 | F7: MARCIO APARECIDO CAVALHEIRO | G7: 20069950 | I7: 373114 | J7: Premio maio - ok | L7: Lençois Paulista | M7: ok - apoiando M4 | N7: ok | R7: MARIO FRAIZ COELHO MAIA DE ANDRADE | S7: MOD.04 | T7: 371174 - CARREG PROP MOD 4 | U7: MARCIO APARECIDO CAVALHEIRO
A8: 37016808 | B8: DANIEL RODRIGUES FOGACA | C8: MOD.02 | D8: MOTORISTA II | E8: 45356 | F8: JHON FELIPE SENOSKI | G8: 20065307 | I8: 373114 | J8: Premio maio - ok | L8: itapeva | M8: ok | N8: CC Operadores Estradas próprio dar downgrade nas vagas que temos (7vagas) | R8: MARIO FRAIZ COELHO MAIA DE ANDRADE | S8: MOD.05 | T8: 371175 - CARREG PROP MOD 5 | U8: THIAGO MARIA PROENCA ALMEIDA
B9: ALEX CRISTIANO MENDES | C9: MOD.02 | D9: MOTORISTA II | E9: 45356 | F9: JHON FELIPE SENOSKI | H9: =VLOOKUP(Apoio_Transp[[#This Row],[MATRÍCULA]],[2]!Tabela1[[#All],[ID SAP]:[NOMENCLATURA DA POSIÇÃO]],6,0) -> #REF! | I9: 373116 | K9: 45534 | N9: verifcar urgente (esta em vaga de motorista), downgrade de III para II | R9: MARIO FRAIZ COELHO MAIA DE ANDRADE | S9: MOD.06 | T9: 371176 - CARREG PROP MOD 6 | U9: CASSIO THOMAS DA SILVEIRA
A10: 37013693 | B10: Deoclecio Antonio Ribeiro | C10: MOD.03 | D10: OPERADOR DE ESTRADAS III | E10: 45139 | F10: JHON FELIPE SENOSKI | G10: 20056256 | I10: 373114 | J10: Premio maio - ok | L10: Itatinga | M10: ok | N10: ok | R10: MARIO FRAIZ COELHO MAIA DE ANDRADE | S10: MOD.07 | T10: 371177 - CARREG PROP MOD 7 | U10: CASSIO THOMAS DA SILVEIRA
B11: JOSE ROBERTO DE OLIVEIRA II | C11: MOD.02 | D11: MOTORISTA II | F11: JHON FELIPE SENOSKI | H11: =VLOOKUP(Apoio_Transp[[#This Row],[MATRÍCULA]],[2]!Tabela1[[#All],[ID SAP]:[NOMENCLATURA DA POSIÇÃO]],6,0) -> #REF! | K11: 45369 | N11: ok | R11: MARIO FRAIZ COELHO MAIA DE ANDRADE | S11: MOD.08 | T11: 371178 - CARREG PROP MOD 8 | U11: THIAGO MARIA PROENCA ALMEIDA
A12: 37017119 | B12: DIEGO ALENCAR FERREIRA | C12: MOD.03 | D12: OPERADOR DE ESTRADAS III | E12: 45384 | F12: JHON FELIPE SENOSKI | G12: 20067433 | H12: =VLOOKUP(Apoio_Transp[[#This Row],[MATRÍCULA]],[2]!Tabela1[[#All],[ID SAP]:[NOMENCLATURA DA POSIÇÃO]],6,0) -> #REF! | I12: 373114 | K12: 45734 | L12: Itatinga | M12: ok | N12: ok | R12: MARIO FRAIZ COELHO MAIA DE ANDRADE | T12: 373105 - COORD CARREGAMENTO
A13: 37013054 | B13: FERNANDO ALVES DE OLIVEIRA | C13: MOD.02 | D13: OPERADOR DE ESTRADAS III | E13: 45097 | F13: JHON FELIPE SENOSKI | G13: 20052406 | I13: 373114 | J13: Premio maio - ok | L13: itapeva | M13: ok | N13: ok
A14: 37016936 | B14: EDSON JOSE DE SOUZA | C14: MOD.04 | D14: MOTORISTA I | E14: 45370 | F14: MARCIO APARECIDO CAVALHEIRO | G14: 20065887 | I14: 373114 | J14: Premio maio - ok | L14: agudos | M14: ok | N14: ok
B15: DANILO TEIXEIRA DO LIVRAMENTO | C15: MOD.05 | D15: MOTORISTA II | E15: 45370 | F15: THIAGO MARIA PROENCA ALMEIDA | H15: =VLOOKUP(Apoio_Transp[[#This Row],[MATRÍCULA]],[2]!Tabela1[[#All],[ID SAP]:[NOMENCLATURA DA POSIÇÃO]],6,0) -> #REF! | K15: 45477 | N15: É nosso mas adequar no CC 373116
A16: 37016767 | B16: JESUS NAZARENO DE MOURA | C16: MOD.02 | D16: OPERADOR DE ESTRADAS III | E16: 45356 | F16: JHON FELIPE SENOSKI | G16: 20065261 | I16: 373114 | J16: Premio maio - ok | L16: itapeva | M16: ok | N16: ok
A17: 37016873 | B17: JOAO VICTOR MAMUD FRANCO CALACO | C17: MOD.03 | D17: OPERADOR DE ESTRADAS III | E17: 45363 | F17: JHON FELIPE SENOSKI | G17: 20065469 | I17: 373114 | J17: Premio maio - ok | L17: Itatinga | M17: ok | N17: ok
A18: 37016812 | B18: JULIANO HELIO DA SILVA | C18: MOD.02 | D18: OPERADOR DE ESTRADAS III | E18: 45356 | F18: JHON FELIPE SENOSKI | G18: 20065311 | I18: 373114 | J18: Premio maio - ok | L18: itapeva | M18: ok | N18: ok
A19: 37016671 | B19: LAUDELINO RIBAS DE OLIVEIRA MATOS | C19: MOD.02 | D19: OPERADOR DE ESTRADAS III | E19: 45342 | F19: JHON FELIPE SENOSKI | G19: 20064772 | I19: 373114 | J19: Premio maio - ok | L19: itapeva | M19: ok | N19: ok
A20: 37018016 | B20: JOSE ADALBERTO BISPO | C20: MOD.01 | D20: MOTORISTA II | E20: 45447 | F20: MARCIO APARECIDO CAVALHEIRO | G20: 20071375 | I20: 373114 | J20: Premio maio - ok | L20: Lençois Paulista | M20: Estradas | N20: ok
A21: 37017036 | B21: EDERVANDSON BRITO FERREIRA | C21: MOD.08 | D21: OPERADOR DE ESTRADAS II | E21: 45384 | F21: THIAGO MARIA PROENCA ALMEIDA | G21: 20066635 | I21: 373114 | J21: Premio maio - ok | L21: Bauru | M21: Não receberá | O21: FEITO
A22: 37017084 | B22: EDSON EDVALDO CAMILLO | C22: MOD.08 | D22: OPERADOR DE ESTRADAS II | E22: 45384 | F22: THIAGO MARIA PROENCA ALMEIDA | G22: 20067078 | I22: 373114 | J22: Premio maio - ok | L22: Bauru | M22: Não receberá
A23: 37016917 | B23: Edson Martins | C23: MOD.05 | D23: MOTORISTA II | E23: 45370 | F23: THIAGO MARIA PROENCA ALMEIDA | G23: 20065867 | H23: =VLOOKUP(Apoio_Transp[[#This Row],[MATRÍCULA]],[2]!Tabela1[[#All],[ID SAP]:[NOMENCLATURA DA POSIÇÃO]],6,0) -> #REF! | I23: 373114 | K23: 45729 | L23: Bauru | M23: ok | N23: verifcar urgente (esta em vaga de motorista), passar para vaga aberta de III
A24: 37016864 | B24: MARCOS ROBERTO DE REZENDE | C24: MOD.03 | D24: MOTORISTA II | E24: 45363 | F24: JHON FELIPE SENOSKI | G24: 20065443 | I24: 373114 | J24: Premio maio - ok | L24: Itatinga | M24: ok | N24: ok
B25: Andre Jacinto | C25: MOD.04 | D25: MOTORISTA I | E25: 45370 | F25: MARCIO APARECIDO CAVALHEIRO | H25: =VLOOKUP(Apoio_Transp[[#This Row],[MATRÍCULA]],[2]!Tabela1[[#All],[ID SAP]:[NOMENCLATURA DA POSIÇÃO]],6,0) -> #REF! | K25: 45490 | N25: ok
B26: ALMIR RODRIGUES ALMEIDA | C26: MOD.04 | D26: OPERADOR DE ESTRADAS III | E26: 45356 | F26: MARCIO APARECIDO CAVALHEIRO | G26: 20065257 | H26: =VLOOKUP(Apoio_Transp[[#This Row],[MATRÍCULA]],[2]!Tabela1[[#All],[ID SAP]:[NOMENCLATURA DA POSIÇÃO]],6,0) -> #REF! | I26: 373116 | K26: 45534 | N26: É nosso mas adequar no CC 373116
B27: ELIAS CASTRO DA SILVA | C27: MOD.05 | D27: MOTORISTA II | E27: 45398 | F27: THIAGO MARIA PROENCA ALMEIDA | H27: =VLOOKUP(Apoio_Transp[[#This Row],[MATRÍCULA]],[2]!Tabela1[[#All],[ID SAP]:[NOMENCLATURA DA POSIÇÃO]],6,0) -> #REF! | I27: 373116 | K27: 45463 | N27: verifcar urgente (esta em vaga de motorista), passar para vaga aberta de III
A28: 37017042 | B28: FABIANO VIEIRA | C28: MOD.05 | D28: MOTORISTA II | E28: 45384 | F28: THIAGO MARIA PROENCA ALMEIDA | G28: 20066642 | I28: 373114 | J28: Premio maio - ok | L28: Bauru | M28: ok | N28: ok | O28: FEITO
A29: 37021547 | B29: JEFFERSON CARDOSO DE PAULA | C29: MOD.08 | D29: MOTORISTA II | E29: 45755 | F29: THIAGO MARIA PROENCA ALMEIDA | G29: 20089413 | I29: 373114 | J29: pagar proporcional
A30: 37017104 | B30: JESUS FERNANDO FERREIRA DE OLIVEIRA | C30: MOD.05 | D30: OPERADOR DE ESTRADAS III | E30: 45384 | F30: THIAGO MARIA PROENCA ALMEIDA | G30: 20067418 | I30: 373114 | J30: Premio maio - ok | L30: Bauru | M30: ok | N30: ok
A31: 37017097 | B31: JOAO KLEBER ANTONIO LOPES | C31: MOD.05 | D31: OPERADOR DE ESTRADAS II | E31: 45384 | F31: THIAGO MARIA PROENCA ALMEIDA | G31: 20067411 | I31: 373114 | J31: Premio maio - ok | L31: Bauru | M31: ok
A32: 37016772 | B32: JOSE NIVALDO DE OLIVEIRA | C32: MOD.05 | D32: OPERADOR DE ESTRADAS III | E32: 45356 | F32: THIAGO MARIA PROENCA ALMEIDA | G32: 20060083 | I32: 373114 | J32: Premio maio - ok | L32: Bauru | M32: ok | N32: ok
A33: 37016869 | B33: RODRIGO ALVES DE MELLO | C33: MOD.03 | D33: MOTORISTA II | E33: 45363 | F33: JHON FELIPE SENOSKI | G33: 20065465 | I33: 373114 | J33: Premio maio - ok | L33: Itatinga | M33: ok | N33: ok
A34: 37016956 | B34: LEONARDO DE MELO ARF | C34: MOD.05 | D34: OPERADOR DE ESTRADAS III | E34: 45370 | F34: THIAGO MARIA PROENCA ALMEIDA | G34: 20065907 | I34: 373114 | J34: Premio maio - ok | L34: Bauru | M34: ok | N34: ok | O34: FALTOU
A35: 37021417 | B35: MARCELO MACHADO MARTINS DE SOUZA | C35: MOD.05 | D35: MOTORISTA II | E35: 45748 | F35: THIAGO MARIA PROENCA ALMEIDA | G35: 20088837 | I35: 373114 | J35: pagar proporcional
A36: 37020099 | B36: Luciano Antonio Fiques | C36: MOD.04 | D36: OPERADOR DE ESTRADAS III | E36: 45629 | F36: MARCIO APARECIDO CAVALHEIRO | G36: 20062977 | I36: 373114 | J36: Premio maio - ok
A37: 37017990 | B37: MARCIO VICENTE MENDES | C37: MOD.01 | D37: OPERADOR DE ESTRADAS III | E37: 45447 | F37: MARCIO APARECIDO CAVALHEIRO | G37: 20071349 | I37: 373114 | J37: Premio maio - ok | L37: Lençois Paulista | M37: ok - apoiando M4 | N37: ok
A38: 37020198 | B38: Maurício Fernandes de Oliveira | C38: MOD.01 | D38: OPERADOR DE ESTRADAS III | E38: 45629 | F38: MARCIO APARECIDO CAVALHEIRO | G38: 20083048 | I38: 373114 | J38: Premio maio - ok
A39: 37014355 | B39: REGINALDO APARECIDO VAZ | C39: MOD.01 | D39: OPERADOR DE ESTRADAS III | E39: 45174 | F39: MARCIO APARECIDO CAVALHEIRO | G39: 20058490 | I39: 373114 | J39: Premio maio - ok | L39: Lençois Paulista | M39: ok - apoiando M4 | N39: É nosso mas adequar no CC 373116
A40: 37013705 | B40: ROBERTO OLIVEIRA SANTOS | C40: MOD.04 | D40: OPERADOR DE ESTRADAS III | E40: 45139 | F40: MARCIO APARECIDO CAVALHEIRO | G40: 20056287 | I40: 373114 | J40: Premio maio - ok | L40: agudos | M40: ok | N40: ok
...

Sheet ESCOPO-VAGAS
A1: VAGAS JÁ DIRECIONADAS | G1: ESCOPO ASSIST. E OPER. | L1: ESCOPO APOIO
A2: Módulo | B2: Colaborador | C2: Cargo | D2: Gestor | E2: STATUS | G2: Módulo | H2: Assistente | I2: Quantidade | J2: Diferença | L2: Módulo | M2: Motorista | N2: Quantidade | O2: Diferença
A3: 6 | B3: Gregory Willian Javarotti | C3: Motorista II | D3: CASSIO THOMAS DA SILVEIRA | E3: Entrando | G3: 1 | H3: =IF(GETPIVOTDATA("COLABORADOR",DINAMICS1!$A$3,"MÓDULO2","MOD.01","SITUACAO","Assistente Operador Carregamento Grua") >= 'ESCOPO-VAGAS'!$I$22,"Completo","incompleto") -> Completo | I3: =GETPIVOTDATA("COLABORADOR",DINAMICS1!$A$3,"MÓDULO2","MOD.01","SITUACAO","Assistente Operador Carregamento Grua") -> 8 | J3: =I3-$I$22 -> 1 | L3: 1 | M3: =IF(N3>=$N$23,"Completo","Incompleto") -> Completo | N3: =SUM(DINAMICS1!B19:C19) -> 3 | O3: =N3-$N$23 -> 0
A4: 6 | B4: Washington Mariano | C4: OPERADOR DE ESTRADAS III | D4: CASSIO THOMAS DA SILVEIRA | E4: Entrando | G4: 2 | H4: =IF(GETPIVOTDATA("COLABORADOR",DINAMICS1!$A$3,"MÓDULO2","MOD.02","SITUACAO","Assistente Operador Carregamento Grua")>='ESCOPO-VAGAS'!$I$22,"Completo","incompleto") -> Completo | I4: =GETPIVOTDATA("COLABORADOR",DINAMICS1!$A$3,"MÓDULO2","MOD.02","SITUACAO","Assistente Operador Carregamento Grua") -> 7 | J4: =I4-$I$22 -> 0 | L4: 2 | M4: =IF(N4>=$N$23,"Completo","Incompleto") -> Completo | N4: =SUM(DINAMICS1!B20:C20) -> 3 | O4: =N4-$N$23 -> 0
A5: 6 | B5: Marcos de Oliveira Amorim | C5: Oper Maqs Florestais I Grua | D5: CASSIO THOMAS DA SILVEIRA | E5: Entrando | G5: 3 | H5: =IF(GETPIVOTDATA("COLABORADOR",DINAMICS1!$A$3,"MÓDULO2","MOD.03","SITUACAO","Assistente Operador Carregamento Grua")>='ESCOPO-VAGAS'!$I$22,"Completo","Imcompleto") -> Completo | I5: =GETPIVOTDATA("COLABORADOR",DINAMICS1!$A$3,"MÓDULO2","MOD.03","SITUACAO","Assistente Operador Carregamento Grua") -> 7 | J5: =I5-$I$22 -> 0 | L5: 3 | M5: =IF(N5>=$N$23,"Completo","Incompleto") -> Completo | N5: =SUM(DINAMICS1!B21:C21) -> 3 | O5: =N5-$N$23 -> 0
A6: 6 | B6: Paulo César Bueno | C6: Oper Maqs Florestais I Grua | D6: CASSIO THOMAS DA SILVEIRA | E6: Entrando | G6: 4 | H6: =IF(GETPIVOTDATA("COLABORADOR",DINAMICS1!$A$3,"MÓDULO2","MOD.04","SITUACAO","Assistente Operador Carregamento Grua")>='ESCOPO-VAGAS'!$I$22,"Completo","Imcompleto") -> Imcompleto | I6: =GETPIVOTDATA("COLABORADOR",DINAMICS1!$A$3,"MÓDULO2","MOD.04","SITUACAO","Assistente Operador Carregamento Grua") -> 6 | J6: =I6-$I$22 -> -1 | L6: 4 | M6: =IF(N6>=$N$23,"Completo","Incompleto") -> Completo | N6: =SUM(DINAMICS1!B22:C22) -> 3 | O6: =N6-$N$23 -> 0
A7: 8 | B7: VAGA ABERTA | C7: Motorista II | D7: THIAGO MARIA PROENCA ALMEIDA | E7: VERIFICANDO COM O SUPERVISOR | G7: 5 | H7: =IF(GETPIVOTDATA("COLABORADOR",DINAMICS1!$A$3,"MÓDULO2","MOD.05","SITUACAO","Assistente Operador Carregamento Grua")>='ESCOPO-VAGAS'!$I$22,"Completo","Imcompleto") -> Imcompleto | I7: =GETPIVOTDATA("COLABORADOR",DINAMICS1!$A$3,"MÓDULO2","MOD.05","SITUACAO","Assistente Operador Carregamento Grua") -> 6 | J7: =I7-$I$22 -> -1 | L7: 5 | M7: =IF(N7>=$N$23,"Completo","Incompleto") -> Completo | N7: =SUM(DINAMICS1!B23:C23) -> 3 | O7: =N7-$N$23 -> 0
A8: 8 | B8: VAGA ABERTA | C8: Motorista II | D8: THIAGO MARIA PROENCA ALMEIDA | E8: VERIFICANDO COM O SUPERVISOR | G8: 6 | H8: =IF(GETPIVOTDATA("COLABORADOR",DINAMICS1!$A$3,"MÓDULO2","MOD.06","SITUACAO","Assistente Operador Carregamento Grua")>='ESCOPO-VAGAS'!$I$22,"Completo","Imcompleto") -> Imcompleto | I8: =GETPIVOTDATA("COLABORADOR",DINAMICS1!$A$3,"MÓDULO2","MOD.06","SITUACAO","Assistente Operador Carregamento Grua") -> 6 | J8: =I8-$I$22 -> -1 | L8: 6 | M8: =IF(N8>=$N$23,"Completo","Incompleto") -> Completo | N8: =SUM(DINAMICS1!B24:C24) -> 3 | O8: =N8-$N$23 -> 0
A9: 8 | B9: VAGA ABERTA | C9: Motorista II | D9: THIAGO MARIA PROENCA ALMEIDA | E9: VERIFICANDO COM O SUPERVISOR | G9: 7 | H9: =IF(GETPIVOTDATA("COLABORADOR",DINAMICS1!$A$3,"MÓDULO2","MOD.07","SITUACAO","Assistente Operador Carregamento Grua")>='ESCOPO-VAGAS'!$I$22,"Completo","Imcompleto") -> Imcompleto | I9: =GETPIVOTDATA("COLABORADOR",DINAMICS1!$A$3,"MÓDULO2","MOD.07","SITUACAO","Assistente Operador Carregamento Grua") -> 6 | J9: =I9-$I$22 -> -1 | L9: 7 | M9: =IF(N9>=$N$23,"Completo","Incompleto") -> Completo | N9: =SUM(DINAMICS1!B25:C25) -> 3 | O9: =N9-$N$23 -> 0
A10: 5 | B10: VAGA ABERTA | C10: Oper Maqs Florestais I Grua | D10: THIAGO MARIA PROENCA ALMEIDA | E10: VERIFICANDO COM O SUPERVISOR | G10: 8 | H10: =IF(GETPIVOTDATA("COLABORADOR",DINAMICS1!$A$3,"MÓDULO2","MOD.08","SITUACAO","Assistente Operador Carregamento Grua")>='ESCOPO-VAGAS'!$I$22,"Completo","incompleto") -> Completo | I10: =GETPIVOTDATA("COLABORADOR",DINAMICS1!$A$3,"MÓDULO2","MOD.08","SITUACAO","Assistente Operador Carregamento Grua") -> 7 | J10: =I10-$I$22 -> 0 | L10: 8 | M10: =IF(N10>=$N$23,"Completo","Incompleto") -> Incompleto | N10: =SUM(DINAMICS1!B26:C26) -> 1 | O10: =N10-$N$23 -> -2
A11: 5/8 | B11: VAGA ABERTA | C11: TECN OPERACOES FLORESTAIS II | D11: THIAGO MARIA PROENCA ALMEIDA | E11: Em processo de contratação | G11: Módulo | H11: Oper. Grua | I11: Quantidade | J11: Diferença | L11: Módulo | M11: Oper. Estradas | N11: Quantidade | O11: Diferença
G12: 1 | H12: =IF(GETPIVOTDATA("COLABORADOR",DINAMICS1!$A$3,"MÓDULO2","MOD.01","SITUACAO","Oper Maqs Florestais I Grua")>='ESCOPO-VAGAS'!$I$23,"Completo","Incompleto") -> Completo | I12: =GETPIVOTDATA("COLABORADOR",DINAMICS1!$A$3,"MÓDULO2","MOD.01","SITUACAO","Oper Maqs Florestais I Grua") -> 9 | J12: =I12-$I$23 -> 1 | L12: 1 | M12: =IF(N12>=$N$22,"Completo","Incompleto") -> Completo | N12: =SUM(DINAMICS1!D19:F19) -> 4 | O12: =N12-$N$22 -> 0
G13: 2 | H13: =IF(GETPIVOTDATA("COLABORADOR",DINAMICS1!$A$3,"MÓDULO2","MOD.02","SITUACAO","Oper Maqs Florestais I Grua")>='ESCOPO-VAGAS'!$I$23,"Completo","Incompleto") -> Incompleto | I13: =GETPIVOTDATA("COLABORADOR",DINAMICS1!$A$3,"MÓDULO2","MOD.02","SITUACAO","Oper Maqs Florestais I Grua") -> 7 | J13: =I13-$I$23 -> -1 | L13: 2 | M13: =IF(N13>=$N$22,"Completo","Incompleto") -> Completo | N13: =SUM(DINAMICS1!D20:F20) -> 4 | O13: =N13-$N$22 -> 0
G14: 3 | H14: =IF(GETPIVOTDATA("COLABORADOR",DINAMICS1!$A$3,"MÓDULO2","MOD.03","SITUACAO","Oper Maqs Florestais I Grua")>='ESCOPO-VAGAS'!$I$23,"Completo","Incompleto") -> Completo | I14: =GETPIVOTDATA("COLABORADOR",DINAMICS1!$A$3,"MÓDULO2","MOD.03","SITUACAO","Oper Maqs Florestais I Grua") -> 9 | J14: =I14-$I$23 -> 1 | L14: 3 | M14: =IF(N14>=$N$22,"Completo","Incompleto") -> Completo | N14: =SUM(DINAMICS1!D21:F21) -> 4 | O14: =N14-$N$22 -> 0
G15: 4 | H15: =IF(GETPIVOTDATA("COLABORADOR",DINAMICS1!$A$3,"MÓDULO2","MOD.04","SITUACAO","Oper Maqs Florestais I Grua")>='ESCOPO-VAGAS'!$I$23,"Completo","Incompleto") -> Completo | I15: =GETPIVOTDATA("COLABORADOR",DINAMICS1!$A$3,"MÓDULO2","MOD.04","SITUACAO","Oper Maqs Florestais I Grua") -> 8 | J15: =I15-$I$23 -> 0 | L15: 4 | M15: =IF(N15>=$N$22,"Completo","Incompleto") -> Completo | N15: =SUM(DINAMICS1!D22:F22) -> 4 | O15: =N15-$N$22 -> 0
G16: 5 | H16: =IF(GETPIVOTDATA("COLABORADOR",DINAMICS1!$A$3,"MÓDULO2","MOD.05","SITUACAO","Oper Maqs Florestais I Grua")>='ESCOPO-VAGAS'!$I$23,"Completo","Incompleto") -> Completo | I16: =GETPIVOTDATA("COLABORADOR",DINAMICS1!$A$3,"MÓDULO2","MOD.05","SITUACAO","Oper Maqs Florestais I Grua") -> 9 | J16: =I16-$I$23 -> 1 | L16: 5 | M16: =IF(N16>=$N$22,"Completo","Incompleto") -> Completo | N16: =SUM(DINAMICS1!D23:F23) -> 4 | O16: =N16-$N$22 -> 0
G17: 6 | H17: =IF(GETPIVOTDATA("COLABORADOR",DINAMICS1!$A$3,"MÓDULO2","MOD.06","SITUACAO","Oper Maqs Florestais I Grua")>='ESCOPO-VAGAS'!$I$23,"Completo","Incompleto") -> Completo | I17: =GETPIVOTDATA("COLABORADOR",DINAMICS1!$A$3,"MÓDULO2","MOD.06","SITUACAO","Oper Maqs Florestais I Grua") -> 9 | J17: =I17-$I$23 -> 1 | L17: 6 | M17: =IF(N17>=$N$22,"Completo","Incompleto") -> Completo | N17: =SUM(DINAMICS1!D24:F24) -> 4 | O17: =N17-$N$22 -> 0
G18: 7 | H18: =IF(GETPIVOTDATA("COLABORADOR",DINAMICS1!$A$3,"MÓDULO2","MOD.07","SITUACAO","Oper Maqs Florestais I Grua")>='ESCOPO-VAGAS'!$I$23,"Completo","Incompleto") -> Completo | I18: =GETPIVOTDATA("COLABORADOR",DINAMICS1!$A$3,"MÓDULO2","MOD.07","SITUACAO","Oper Maqs Florestais I Grua") -> 10 | J18: =I18-$I$23 -> 2 | L18: 7 | M18: =IF(N18>=$N$22,"Completo","Incompleto") -> Completo | N18: =SUM(DINAMICS1!D25:F25) -> 4 | O18: =N18-$N$22 -> 0
G19: 8 | H19: =IF(GETPIVOTDATA("COLABORADOR",DINAMICS1!$A$3,"MÓDULO2","MOD.08","SITUACAO","Oper Maqs Florestais I Grua")>='ESCOPO-VAGAS'!$I$23,"Completo","Incompleto") -> Completo | I19: =GETPIVOTDATA("COLABORADOR",DINAMICS1!$A$3,"MÓDULO2","MOD.08","SITUACAO","Oper Maqs Florestais I Grua") -> 8 | J19: =I19-$I$23 -> 0 | L19: 8 | M19: =IF(N19>=$N$22,"Completo","Incompleto") -> Completo | N19: =SUM(DINAMICS1!D26:F26) -> 4 | O19: =N19-$N$22 -> 0
H21: Escopo por módulo | M21: Escopo por módulo
H22: Assistentes | I22: 7 | M22: Oper Estradas | N22: 4
H23: Operadores | I23: 8 | M23: Motorista | N23: 3
H24: Total | I24: 15 | M24: Total | N24: 7

Sheet MAPEAMENTO
A1: Unidade | B1: Tipo | C1: Módulo | D1: Coord | E1: Supervisor | F1: Região | G1: Qtde aprox.
A2: Florestal | B2: Carregamento | C2: MOD.01 | D2: Mario Fraiz Coelho Maia de Andrade | E2: Márcio Aparecido Cavalheiro | F2: LENÇÓIS PAULISTA | G2: 24
A3: Florestal | B3: Carregamento | C3: MOD.02 | D3: Mario Fraiz Coelho Maia de Andrade | E3: Jhon Felipe Senoski | F3: ITAPEVA | G3: 24
A4: Florestal | B4: Carregamento | C4: MOD.03 | D4: Mario Fraiz Coelho Maia de Andrade | E4: Jhon Felipe Senoski | F4: ITATINGA | G4: 23
A5: Florestal | B5: Carregamento | C5: MOD.04 | D5: Mario Fraiz Coelho Maia de Andrade | E5: Márcio Aparecido Cavalheiro | F5: AGUDOS | G5: 22
A6: Florestal | B6: Carregamento | C6: MOD.05 | D6: Mario Fraiz Coelho Maia de Andrade | E6: Thiago Maria Proenca Almeida | F6: BAURU | G6: 21
A7: Florestal | B7: Carregamento | C7: MOD.06 | D7: Mario Fraiz Coelho Maia de Andrade | E7: Cássio Thomas da Silveira | F7: LINS | G7: 20
A8: Florestal | B8: Carregamento | C8: MOD.07 | D8: Mario Fraiz Coelho Maia de Andrade | E8: Cássio Thomas da Silveira | F8: MARÍLIA | G8: 23
A9: Florestal | B9: Carregamento | C9: MOD.08 | D9: Mario Fraiz Coelho Maia de Andrade | E9: Thiago Maria Proenca Almeida | F9: BAURU | G9: 22
A10: Florestal | B10: Carregamento | C10: MOD.09(Módulo terceiro) | D10: Angelo Antonio Martins Taparo | E10: Adriano Sanabia Flores Monte Serrat | F10: MATO GROSSO DO SUL | G10: N/A
A11: Florestal | B11: Carregamento | C11: MOD.10 (Módulo terceiro) | D11: Mario Fraiz Coelho Maia de Andrade | E11: Márcio Aparecido Cavalheiro | F11: TERCEIRO (SP) | G11: N/A
A12: Florestal | B12: Carregamento | C12: MOD.11(Módulo terceiro) | D12: Angelo Antonio Martins Taparo | E12: Gilliard Lepinsck | F12: MINAS GERAIS | G12: N/A

Sheet Planilha2
A1: 37017525 | B1: SANTOS GLAUCIO DA SILVA | C1: Op Maquinas Equipamentos III | D1: BRC-01 | E1: EMPRESTADO
A2: 37018016 | B2: JOSE ADALBERTO BISPO | C2: Motorista II | D2: BRC-01 | E2: EMPRESTADO
A3: 37018148 | B3: Alex de Godoi Paino | C3: Motorista II | D3: BRC03 | E3: EMPRESTADO CARREGAMENTO (a partir de 08/08)
A4: 37018408 | B4: Cristiano Silva | C4: Motorista II | D4: BRC03 | E4: EMPRESTADO CARREGAMENTO (a partir de 08/08)
A5: 37017084 | B5: Edson Edvaldo Camilo | C5: Op Maquinas Equipamentos II | D5: BRC-03 | E5: EMPRESTADO CARREGAMENTO (mês fechado)
A6: 37017957 | B6: Cleberson Roberto Perez Lopes | C6: Op Maquinas Equipamentos II | D6: BRC-05 | E6: EMPRESTADO CARREGAMENTO
A7: 37018146 | B7: Fabio Dias Carlos | C7: Motorista II | D7: BRC-05 | E7: EMPRESTADO CARREGAMENTO
A8: 37018150 | B8: Paulo Henrique de Lima Vieira | C8: Op Maquinas Equipamentos III | D8: BRC-05 | E8: EMPRESTADO CARREGAMENTO
A9: 37018142 | B9: José Mariano | C9: Motorista II | D9: BRC-05 | E9: EMPRESTADO CARREGAMENTO
A10: 37017990 | B10: MARCIO VICENTE MENDES | C10: Op Maquinas Equipamentos III
